Workbook

Sheet 365RE
B1: 365 DataScience RE California Database
B2: Practical example
B4: Product | L4: Customer
B5: ID | C5: Building | D5: Year of sale | E5: Month of sale | F5: Type of property | G5: Property # | H5: Area (ft.) | I5: Price | J5: Status | L5: Customer ID | M5: Entity | N5: Name | O5: Surname | P5: Age at time of purchase | Q5: Interval | R5: Y | S5: M | T5: D | U5: Gender | V5: Country | W5: State | X5: Purpose | Y5: Deal satisfaction | Z5: Mortgage | AA5: Source
B6: =C6*1000+G6 -> 1030 | C6: 1 | D6: 2005 | E6: 11 | F6: Apartment | G6: 30 | H6: 743.0856 | I6: 246172.68 | J6: Sold | L6: C0028 | M6: Individual | N6: Madalyn | O6: Mercer | P6: =D6-R6 -> 19 | Q6: =IF(P6<26,"18-25",IF(P6<36,"26-35",IF(P6<46,"36-45",IF(P6<56,"46-55",IF(P6<66,"56-65","65+"))))) -> 18-25 | R6: 1986 | S6: 6 | T6: 21 | U6: F | V6: USA | W6: California | X6: Home | Y6: 5 | Z6: No | AA6: Website
B7: =C7*1000+G7 -> 1029 | C7: 1 | D7: 2005 | E7: 10 | F7: Apartment | G7: 29 | H7: 756.2128 | I7: 246331.9 | J7: Sold | L7: C0027 | M7: Individual | N7: Lara | O7: Carrillo | P7: =IF((D7-R7)=0," ",D7-R7) -> 22 | Q7: =IF(P7<26,"18-25",IF(P7<36,"26-35",IF(P7<46,"36-45",IF(P7<56,"46-55",IF(P7<66,"56-65","65+"))))) -> 18-25 | R7: 1983 | S7: 2 | T7: 24 | U7: F | V7: USA | W7: California | X7: Home | Y7: 5 | Z7: No | AA7: Website
B8: =C8*1000+G8 -> 2002 | C8: 2 | D8: 2007 | E8: 7 | F8: Apartment | G8: 2 | H8: 587.2808 | I8: 209280.91 | J8: Sold | L8: C0112 | M8: Individual | N8: Donavan | O8: Flowers | P8: =IF((D8-R8)=0," ",D8-R8) -> 22 | Q8: =IF(P8<26,"18-25",IF(P8<36,"26-35",IF(P8<46,"36-45",IF(P8<56,"46-55",IF(P8<66,"56-65","65+"))))) -> 18-25 | R8: 1985 | S8: 12 | T8: 27 | U8: M | V8: USA | W8: California | X8: Home | Y8: 1 | Z8: Yes | AA8: Client
B9: =C9*1000+G9 -> 2031 | C9: 2 | D9: 2007 | E9: 12 | F9: Apartment | G9: 31 | H9: 1604.7464 | I9: 452667.01 | J9: Sold | L9: C0160 | M9: Individual | N9: Darien | O9: Dorsey | P9: =IF((D9-R9)=0," ",D9-R9) -> 22 | Q9: =IF(P9<26,"18-25",IF(P9<36,"26-35",IF(P9<46,"36-45",IF(P9<56,"46-55",IF(P9<66,"56-65","65+"))))) -> 18-25 | R9: 1985 | S9: 12 | T9: 27 | U9: M | V9: USA | W9: California | X9: Investment | Y9: 3 | Z9: Yes | AA9: Website
B10: =C10*1000+G10 -> 1049 | C10: 1 | D10: 2004 | E10: 11 | F10: Apartment | G10: 49 | H10: 1375.4508 | I10: 467083.31 | J10: Sold | L10: C0014 | M10: Individual | N10: Alessandra | O10: Perry | P10: =IF((D10-R10)=0," ",D10-R10) -> 25 | Q10: =IF(P10<26,"18-25",IF(P10<36,"26-35",IF(P10<46,"36-45",IF(P10<56,"46-55",IF(P10<66,"56-65","65+"))))) -> 18-25 | R10: 1979 | S10: 5 | T10: 15 | U10: F | V10: USA | W10: California | X10: Home | Y10: 4 | Z10: No | AA10: Agency
B11: =C11*1000+G11 -> 3011 | C11: 3 | D11: 2007 | E11: 9 | F11: Apartment | G11: 11 | H11: 675.19 | I11: 203491.85 | J11: Sold | L11: C0125 | M11: Individual | N11: Kaitlin | O11: Owen | P11: =IF((D11-R11)=0," ",D11-R11) -> 26 | Q11: =IF(P11<26,"18-25",IF(P11<36,"26-35",IF(P11<46,"36-45",IF(P11<56,"46-55",IF(P11<66,"56-65","65+"))))) -> 26-35 | R11: 1981 | S11: 12 | T11: 26 | U11: F | V11: USA | W11: Virginia | X11: Investment | Y11: 5 | Z11: No | AA11: Client
B12: =C12*1000+G12 -> 3026 | C12: 3 | D12: 2007 | E12: 9 | F12: Apartment | G12: 26 | H12: 670.886 | I12: 212520.83 | J12: Sold | L12: C0125 | M12: Individual | N12: Kaitlin | O12: Owen | P12: =IF((D12-R12)=0," ",D12-R12) -> 26 | Q12: =IF(P12<26,"18-25",IF(P12<36,"26-35",IF(P12<46,"36-45",IF(P12<56,"46-55",IF(P12<66,"56-65","65+"))))) -> 26-35 | R12: 1981 | S12: 12 | T12: 26 | U12: F | V12: USA | W12: Virginia | X12: Investment | Y12: 5 | Z12: No | AA12: Agency
B13: =C13*1000+G13 -> 3023 | C13: 3 | D13: 2008 | E13: 1 | F13: Apartment | G13: 23 | H13: 720.8124 | I13: 198591.85 | J13: Sold | L13: C0166 | M13: Individual | N13: Terry | O13: Forbes | P13: =IF((D13-R13)=0," ",D13-R13) -> 26 | Q13: =IF(P13<26,"18-25",IF(P13<36,"26-35",IF(P13<46,"36-45",IF(P13<56,"46-55",IF(P13<66,"56-65","65+"))))) -> 26-35 | R13: 1982 | S13: 5 | T13: 27 | U13: M | V13: USA | W13: California | X13: Home | Y13: 5 | Z13: No | AA13: Client
B14: =C14*1000+G14 -> 1031 | C14: 1 | D14: 2006 | E14: 6 | F14: Apartment | G14: 31 | H14: 782.252 | I14: 265467.68 | J14: Sold | L14: C0034 | M14: Individual | N14: Kole | O14: Shannon | P14: =IF((D14-R14)=0," ",D14-R14) -> 27 | Q14: =IF(P14<26,"18-25",IF(P14<36,"26-35",IF(P14<46,"36-45",IF(P14<56,"46-55",IF(P14<66,"56-65","65+"))))) -> 26-35 | R14: 1979 | S14: 6 | T14: 27 | U14: M | V14: USA | W14: Arizona | X14: Home | Y14: 2 | Z14: Yes | AA14: Website
B15: =C15*1000+G15 -> 4023 | C15: 4 | D15: 2006 | E15: 3 | F15: Apartment | G15: 23 | H15: 794.5184 | I15: 235633.26 | J15: Sold | L15: C0170 | M15: Individual | N15: Emmy | O15: Singh | P15: =IF((D15-R15)=0," ",D15-R15) -> 27 | Q15: =IF(P15<26,"18-25",IF(P15<36,"26-35",IF(P15<46,"36-45",IF(P15<56,"46-55",IF(P15<66,"56-65","65+"))))) -> 26-35 | R15: 1979 | S15: 12 | T15: 3 | U15: F | V15: USA | W15: Virginia | X15: Investment | Y15: 3 | Z15: Yes | AA15: Agency
B16: =C16*1000+G16 -> 1036 | C16: 1 | D16: 2004 | E16: 10 | F16: Apartment | G16: 36 | H16: 1160.3584 | I16: 317473.86 | J16: Sold | L16: C0009 | M16: Individual | N16: Arabella | O16: Ferrell | P16: =IF((D16-R16)=0," ",D16-R16) -> 28 | Q16: =IF(P16<26,"18-25",IF(P16<36,"26-35",IF(P16<46,"36-45",IF(P16<56,"46-55",IF(P16<66,"56-65","65+"))))) -> 26-35 | R16: 1976 | S16: 8 | T16: 17 | U16: F | V16: USA | W16: Oregon | X16: Home | Y16: 1 | Z16: No | AA16: Agency
B17: =C17*1000+G17 -> 1046 | C17: 1 | D17: 2006 | E17: 8 | F17: Apartment | G17: 46 | H17: 1942.5028 | I17: 503790.23 | J17: Sold | L17: C0041 | M17: Individual | N17: Christian | O17: Costa | P17: =IF((D17-R17)=0," ",D17-R17) -> 26 | Q17: =IF(P17<26,"18-25",IF(P17<36,"26-35",IF(P17<46,"36-45",IF(P17<56,"46-55",IF(P17<66,"56-65","65+"))))) -> 26-35 | R17: 1980 | S17: 9 | T17: 14 | U17: M | V17: USA | W17: California | X17: Home | Y17: 5 | Z17: No | AA17: Website
B18: =C18*1000+G18 -> 4035 | C18: 4 | D18: 2007 | E18: 10 | F18: Apartment | G18: 35 | H18: 794.5184 | I18: 217786.38 | J18: Sold | L18: C0057 | M18: Individual | N18: Michelle | O18: Cameron | P18: =IF((D18-R18)=0," ",D18-R18) -> 29 | Q18: =IF(P18<26,"18-25",IF(P18<36,"26-35",IF(P18<46,"36-45",IF(P18<56,"46-55",IF(P18<66,"56-65","65+"))))) -> 26-35 | R18: 1978 | S18: 6 | T18: 4 | U18: F | V18: USA | W18: Nevada | X18: Home | Y18: 3 | Z18: Yes | AA18: Website
... B46: =C46*1000+G46 -> 4005 | C46: 4 | D46: 2007 | E46: 11 | F46: Apartment | G46: 5 | H46: 1121.9452 | I46: 344530.89 | J46: Sold | L46: C0142 | M46: Individual | N46: Kassidy | O46: Vega | P46: =IF((D46-R46)=0," ",D46-R46) -> 35 | Q46: =IF(P46<26,"18-25",IF(P46<36,"26-35",IF(P46<46,"36-45",IF(P46<56,"46-55",IF(P46<66,"56-65","65+"))))) -> 26-35 | R46: 1972 | S46: 5 | T46: 7 | U46: F | V46: USA | W46: California | X46: Home | Y46: 5 | Z46: No | AA46: Website
B47: =C47*1000+G47 -> 1032 | C47: 1 | D47: 2005 | E47: 1 | F47: Apartment | G47: 32 | H47: 782.252 | I47: 215410.28 | J47: Sold | L47: C0015 | M47: Individual | N47: Lauryn | O47: Patrick | P47: =IF((D47-R47)=0," ",D47-R47) -> 36 | Q47: =IF(P47<26,"18-25",IF(P47<36,"26-35",IF(P47<46,"36-45",IF(P47<56,"46-55",IF(P47<66,"56-65","65+"))))) -> 36-45 | R47: 1969 | S47: 10 | T47: 30 | U47: F | V47: Belgium | X47: Home | Y47: 2 | Z47: No | AA47: Agency
B48: =C48*1000+G48 -> 3046 | C48: 3 | D48: 2007 | E48: 8 | F48: Apartment | G48: 46 | H48: 923.208 | I48: 252185.99 | J48: Sold | L48: C0122 | M48: Individual | N48: Brock | O48: Fischer | P48: =IF((D48-R48)=0," ",D48-R48) -> 36 | Q48: =IF(P48<26,"18-25",IF(P48<36,"26-35",IF(P48<46,"36-45",IF(P48<56,"46-55",IF(P48<66,"56-65","65+"))))) -> 36-45 | R48: 1971 | S48: 5 | T48: 29 | U48: M | V48: USA | W48: Kansas | X48: Home | Y48: 3 | Z48: No | AA48: Website
B49: =C49*1000+G49 -> 1041 | C49: 1 | D49: 2005 | E49: 3 | F49: Apartment | G49: 41 | H49: 1434.0928 | I49: 480545.81 | J49: Sold | L49: C0017 | M49: Individual | N49: Memphis | O49: Mcconnell | P49: =IF((D49-R49)=0," ",D49-R49) -> 37 | Q49: =IF(P49<26,"18-25",IF(P49<36,"26-35",IF(P49<46,"36-45",IF(P49<56,"46-55",IF(P49<66,"56-65","65+"))))) -> 36-45 | R49: 1968 | S49: 8 | T49: 25 | U49: M | V49: USA | W49: California | X49: Home | Y49: 2 | Z49: Yes | AA49: Website
B50: =C50*1000+G50 -> 1012 | C50: 1 | D50: 2005 | E50: 3 | F50: Apartment | G50: 12 | H50: 1160.3584 | I50: 300385.62 | J50: Sold | L50: C0020 | M50: Individual | N50: Grant | O50: Weber | P50: =IF((D50-R50)=0," ",D50-R50) -> 37 | Q50: =IF(P50<26,"18-25",IF(P50<36,"26-35",IF(P50<46,"36-45",IF(P50<56,"46-55",IF(P50<66,"56-65","65+"))))) -> 36-45 | R50: 1968 | S50: 9 | T50: 8 | U50: M | V50: USA | W50: California | X50: Home | Y50: 5 | Z50: Yes | AA50: Website
A51: x | B51: =C51*1000+G51 -> 5033 | C51: 5 | D51: 2008 | E51: 5 | F51: Apartment | G51: 33 | H51: 798.2844 | I51: 240539.35 | J51: Sold | L51: C0086 | M51: Individual | N51: Jace | O51: Riggs | P51: =IF((D51-R51)=0," ",D51-R51) -> 37 | Q51: =IF(P51<26,"18-25",IF(P51<36,"26-35",IF(P51<46,"36-45",IF(P51<56,"46-55",IF(P51<66,"56-65","65+"))))) -> 36-45 | R51: 1971 | S51: 8 | T51: 20 | U51: F | V51: USA | W51: California | X51: Home | Y51: 1 | Z51: No | AA51: Website
B52: =C52*1000+G52 -> 4006 | C52: 4 | D52: 2006 | E52: 7 | F52: Apartment | G52: 6 | H52: 733.1864 | I52: 222138.72 | J52: Sold | L52: C0150 | M52: Individual | N52: Emmett | O52: Estes | P52: =IF((D52-R52)=0," ",D52-R52) -> 37 | Q52: =IF(P52<26,"18-25",IF(P52<36,"26-35",IF(P52<46,"36-45",IF(P52<56,"46-55",IF(P52<66,"56-65","65+"))))) -> 36-45 | R52: 1969 | S52: 6 | T52: 5 | U52: M | V52: USA | W52: California | X52: Home | Y52: 3 | Z52: No | AA52: Website
B53: =C53*1000+G53 -> 5040 | C53: 5 | D53: 2007 | E53: 12 | F53: Apartment | G53: 40 | H53: 798.2844 | I53: 228410.05 | J53: Sold | L53: C0156 | M53: Individual | N53: Isis | O53: Rios | P53: =IF((D53-R53)=0," ",D53-R53) -> 37 | Q53: =IF(P53<26,"18-25",IF(P53<36,"26-35",IF(P53<46,"36-45",IF(P53<56,"46-55",IF(P53<66,"56-65","65+"))))) -> 36-45 | R53: 1970 | S53: 4 | T53: 1 | U53: M | V53: USA | W53: California | X53: Investment | Y53: 4 | Z53: No | AA53: Website
B54: =C54*1000+G54 -> 4013 | C54: 4 | D54: 2007 | E54: 1 | F54: Apartment | G54: 13 | H54: 733.1864 | I54: 197053.51 | J54: Sold | L54: C0169 | M54: Individual | N54: Mason | O54: Gilbert | P54: =IF((D54-R54)=0," ",D54-R54) -> 37 | Q54: =IF(P54<26,"18-25",IF(P54<36,"26-35",IF(P54<46,"36-45",IF(P54<56,"46-55",IF(P54<66,"56-65","65+"))))) -> 36-45 | R54: 1970 | S54: 7 | T54: 31 | U54: M | V54: USA | W54: Colorado | X54: Home | Y54: 2 | Z54: No | AA54: Agency
B55: =C55*1000+G55 -> 1003 | C55: 1 | D55: 2005 | E55: 6 | F55: Office | G55: 3 | H55: 717.0464 | I55: 193660.62 | J55: Sold | L55: C0022 | M55: Individual | N55: Zain | O55: Horne | P55: =IF((D55-R55)=0," ",D55-R55) -> 38 | Q55: =IF(P55<26,"18-25",IF(P55<36,"26-35",IF(P55<46,"36-45",IF(P55<56,"46-55",IF(P55<66,"56-65","65+"))))) -> 36-45 | R55: 1967 | S55: 4 | T55: 13 | U55: M | V55: USA | W55: Arizona | X55: Home | Y55: 1 | Z55: Yes | AA55: Website
B56: =C56*1000+G56 -> 2009 | C56: 2 | D56: 2007 | E56: 3 | F56: Apartment | G56: 9 | H56: 747.4972 | I56: 237060.15 | J56: Sold | L56: C0072 | M56: Individual | N56: Dayton | O56: Hatfield | P56: =IF((D56-R56)=0," ",D56-R56) -> 38 | Q56: =IF(P56<26,"18-25",IF(P56<36,"26-35",IF(P56<46,"36-45",IF(P56<56,"46-55",IF(P56<66,"56-65","65+"))))) -> 36-45 | R56: 1969 | S56: 4 | T56: 19 | U56: M | V56: USA | W56: Colorado | X56: Investment | Y56: 4 | Z56: Yes | AA56: Agency
B57: =C57*1000+G57 -> 4024 | C57: 4 | D57: 2007 | E57: 11 | F57: Apartment | G57: 24 | H57: 1121.9452 | I57: 372001.7 | J57: Sold | L57: C0136 | M57: Individual | N57: Annabel | O57: Robles | P57: =IF((D57-R57)=0," ",D57-R57) -> 38 | Q57: =IF(P57<26,"18-25",IF(P57<36,"26-35",IF(P57<46,"36-45",IF(P57<56,"46-55",IF(P57<66,"56-65","65+"))))) -> 36-45 | R57: 1969 | S57: 10 | T57: 14 | U57: F | V57: USA | W57: California | X57: Home | Y57: 5 | Z57: Yes | AA57: Website
B58: =C58*1000+G58 -> 4012 | C58: 4 | D58: 2007 | E58: 11 | F58: Apartment | G58: 12 | H58: 1121.9452 | I58: 290031.26 | J58: Sold | L58: C0149 | M58: Individual | N58: Kayden | O58: Olsen | P58: =IF((D58-R58)=0," ",D58-R58) -> 38 | Q58: =IF(P58<26,"18-25",IF(P58<36,"26-35",IF(P58<46,"36-45",IF(P58<56,"46-55",IF(P58<66,"56-65","65+"))))) -> 36-45 | R58: 1969 | S58: 10 | T58: 17 | U58: F | V58: USA | W58: California | X58: Home | Y58: 5 | Z58: No | AA58: Website
B59: =C59*1000+G59 -> 1035 | C59: 1 | D59: 2004 | E59: 10 | F59: Apartment | G59: 35 | H59: 827.8744 | I59: 238811.06 | J59: Sold | L59: C0011 | M59: Individual | N59: Davion | O59: Stout | P59: =IF((D59-R59)=0," ",D59-R59) -> 39 | Q59: =IF(P59<26,"18-25",IF(P59<36,"26-35",IF(P59<46,"36-45",IF(P59<56,"46-55",IF(P59<66,"56-65","65+"))))) -> 36-45 | R59: 1965 | S59: 7 | T59: 20 | U59: M | V59: USA | W59: Nevada | X59: Home | Y59: 1 | Z59: Yes | AA59: Agency
B60: =C60*1000+G60 -> 2017 | C60: 2 | D60: 2007 | E60: 3 | F60: Apartment | G60: 17 | H60: 747.4972 | I60: 199054.2 | J60: Sold | L60: C0073 | M60: Individual | N60: Kevin | O60: Mata | P60: =IF((D60-R60)=0," ",D60-R60) -> 39 | Q60: =IF(P60<26,"18-25",IF(P60<36,"26-35",IF(P60<46,"36-45",IF(P60<56,"46-55",IF(P60<66,"56-65","65+"))))) -> 36-45 | R60: 1968 | S60: 10 | T60: 12 | U60: M | V60: USA | W60: Colorado | X60: Investment | Y60: 2 | Z60: No | AA60: Agency
B61: =C61*1000+G61 -> 4051 | C61: 4 | D61: 2007 | E61: 3 | F61: Apartment | G61: 51 | H61: 1608.8352 | I61: 496266.41 | J61: Sold | L61: C0110 | M61: Individual | N61: Kareem | O61: Liu | P61: =IF((D61-R61)=0," ",D61-R61) -> 39 | Q61: =IF(P61<26,"18-25",IF(P61<36,"26-35",IF(P61<46,"36-45",IF(P61<56,"46-55",IF(P61<66,"56-65","65+"))))) -> 36-45 | R61: 1968 | S61: 5 | T61: 11 | U61: F | V61: USA | W61: California | X61: Home | Y61: 4 | Z61: Yes | AA61: Website
B62: =C62*1000+G62 -> 3014 | C62: 3 | D62: 2007 | E62: 7 | F62: Apartment | G62: 14 | H62: 1132.0596 | I62: 346906.89 | J62: Sold | L62: C0111 | M62: Individual | N62: Grace | O62: Stein | P62: =IF((D62-R62)=0," ",D62-R62) -> 39 | Q62: =IF(P62<26,"18-25",IF(P62<36,"26-35",IF(P62<46,"36-45",IF(P62<56,"46-55",IF(P62<66,"56-65","65+"))))) -> 36-45 | R62: 1968 | S62: 12 | T62: 20 | U62: F | V62: USA | W62: California | X62: Home | Y62: 3 | Z62: Yes | AA62: Website
B63: =C63*1000+G63 -> 2051 | C63: 2 | D63: 2007 | E63: 9 | F63: Apartment | G63: 51 | H63: 1383.8436 | I63: 376964.62 | J63: Sold | L63: C0123 | M63: Individual | N63: Lydia | O63: Tate | P63: =IF((D63-R63)=0," ",D63-R63) -> 39 | Q63: =IF(P63<26,"18-25",IF(P63<36,"26-35",IF(P63<46,"36-45",IF(P63<56,"46-55",IF(P63<66,"56-65","65+"))))) -> 36-45 | R63: 1968 | S63: 8 | T63: 14 | U63: F | V63: USA | W63: California | X63: Home | Y63: 3 | Z63: Yes | AA63: Website
B64: =C64*1000+G64 -> 2025 | C64: 2 | D64: 2007 | E64: 2 | F64: Apartment | G64: 25 | H64: 927.8348 | I64: 315733.15 | J64: Sold | L64: C0070 | M64: Individual | N64: Aleksandra | O64: Karenina | P64: =IF((D64-R64)=0," ",D64-R64) -> 40 | Q64: =IF(P64<26,"18-25",IF(P64<36,"26-35",IF(P64<46,"36-45",IF(P64<56,"46-55",IF(P64<66,"56-65","65+"))))) -> 36-45 | R64: 1967 | S64: 6 | T64: 13 | U64: F | V64: Russia | X64: Home | Y64: 1 | Z64: No | AA64: Agency
B65: =C65*1000+G65 -> 3047 | C65: 3 | D65: 2007 | E65: 3 | F65: Apartment | G65: 47 | H65: 669.1644 | I65: 188273.73 | J65: Sold | L65: C0075 | M65: Individual | N65: Sincere | O65: Hansen | P65: =IF((D65-R65)=0," ",D65-R65) -> 40 | Q65: =IF(P65<26,"18-25",IF(P65<36,"26-35",IF(P65<46,"36-45",IF(P65<56,"46-55",IF(P65<66,"56-65","65+"))))) -> 36-45 | R65: 1967 | S65: 1 | T65: 19 | U65: F | V65: USA | W65: California | X65: Investment | Y65: 2 | Z65: Yes | AA65: Agency
B66: =C66*1000+G66 -> 2046 | C66: 2 | D66: 2007 | E66: 3 | F66: Apartment | G66: 46 | H66: 928.1576 | I66: 253831.02 | J66: Sold | L66: C0076 | M66: Individual | N66: Luke | O66: Lynn | P66: =IF((D66-R66)=0," ",D66-R66) -> 40 | Q66: =IF(P66<26,"18-25",IF(P66<36,"26-35",IF(P66<46,"36-45",IF(P66<56,"46-55",IF(P66<66,"56-65","65+"))))) -> 36-45 | R66: 1967 | S66: 2 | T66: 7 | U66: M | V66: USA | W66: California | X66: Home | Y66: 2 | Z66: Yes | AA66: Agency
B67: =C67*1000+G67 -> 5016 | C67: 5 | D67: 2007 | E67: 6 | F67: Apartment | G67: 16 | H67: 798.4996 | I67: 278575.87 | J67: Sold | L67: C0105 | M67: Individual | N67: Myla | O67: Ewing | P67: =IF((D67-R67)=0," ",D67-R67) -> 40 | Q67: =IF(P67<26,"18-25",IF(P67<36,"26-35",IF(P67<46,"36-45",IF(P67<56,"46-55",IF(P67<66,"56-65","65+"))))) -> 36-45 | R67: 1967 | S67: 2 | T67: 3 | U67: F | V67: USA | W67: Oregon | X67: Investment | Y67: 2 | Z67: No | AA67: Client
B68: =C68*1000+G68 -> 4041 | C68: 4 | D68: 2007 | E68: 10 | F68: Apartment | G68: 41 | H68: 1305.6184 | I68: 402081.8 | J68: Sold | L68: C0135 | M68: Individual | N68: Morgan | O68: Glass | P68: =IF((D68-R68)=0," ",D68-R68) -> 40 | Q68: =IF(P68<26,"18-25",IF(P68<36,"26-35",IF(P68<46,"36-45",IF(P68<56,"46-55",IF(P68<66,"56-65","65+"))))) -> 36-45 | R68: 1967 | S68: 5 | T68: 12 | U68: M | V68: USA | W68: Utah | X68: Home | Y68: 5 | Z68: No | AA68: Agency
...

Sheet Task 1
B1: 365 DataScience RE California Database
B2: Types of data and levels of measurement
B4: Task 1: What are the types of data and the levels of measurement of the following variables: Cust ID, Mortgage, Year of sale
C7: Type of data | D7: Level of measurement
B8: Cust ID | C8: Numerical | D8: Ratio
B9: Mortgage | C9: Categorical | D9: Nominal
B10: Year of sale | C10: Categorical | D10: Ordinal
B13: Variable | C13: Type of data | D13: Level of measurement | E13: Comment
B14: Cust ID | C14: Categorical | D14: Nominal | E14: This variable has the same properties as ID.
B15: Mortgage | C15: Categorical | D15: Nominal | E15: This is a Binary variable. Like a Yes/No question or Gender.
B16: Year of sale | C16: Numerical, discrete | D16: Interval | E16: Year is a numerical variable. It is always discrete. The level of measurement is questionable, but we would treat it as interval, as the 0 year would be the time when the Big Bang happened. The current BC-AD calendar was arbitrary chosen (similarly to degrees Celsius and Fahrenheit).

Sheet Tasks 2,3,4
B1: 365 DataScience RE California Database
B2: Histograms. Graphing numerical data
B4: Task 2: Create a frequency distribution graph representing the price (that is a histogram with the highest possible number of bins - 267). Use data on all apartments and offices, no matter if sold or not.
B5: Task 3: Create a histogram which represents the Price variable. Choose interval width (bins) of length $100,000. If you don't know how to do that, refer to the Course notes on descriptive statistics provided with the first lecture in this section.
B6: Use the data on all properties, no matter if sold or not.
B7: Task 4: Interpret the results.
E43: Graph (2): Property prices are right skewed (meaning a few very expensive properties but the majority at around the $217K mark) | P43: Graph (1): Most of the property prices are concetrated around the $199k to $292K mark

Sheet Task 5
B1: 365 DataScience RE California Database
B2: Scatter plot. Plotting numerical data; establishing relationship between variables.
B4: Task 5: Create a scatter plot showing the relationship between Price and Area. Use the data on all properties, no matter if sold or not. Interpret the results.
D6: Output (price) should always be on they-axis
D36: There is a high correlation between the area and price

Sheet Tasks 6,7
B1: 365 DataScience RE California Database
B2: Frequency distribution table. Pareto diagram.
B4: Task 6: Create a frequency distribution table, where you list all the countries from which the company has buyers (country vs number of buyers). Count the absolute frequency, the relative frequency and the cumulative frequency.
B5: Task 7: Create a Pareto diagram representing the data.
C9: Country | D9: Absolute Frequency | E9: Relative Frequency | F9: Cumulative Frequency
C10: USA | D10: =COUNTIF('365RE'!$V$6:$V$201,'Tasks 6,7'!C10) -> 177 | E10: =D10/$D$18 -> 0.90769231 | F10: =E10 -> 0.90769231
C11: Canada | D11: =COUNTIF('365RE'!$V$6:$V$201,'Tasks 6,7'!C11) -> 7 | E11: =D11/$D$18 -> 0.035897436 | F11: =F10+E11 -> 0.94358974
C12: Russia | D12: =COUNTIF('365RE'!$V$6:$V$201,'Tasks 6,7'!C12) -> 4 | E12: =D12/$D$18 -> 0.020512821 | F12: =F11+E12 -> 0.96410256
C13: Belgium | D13: =COUNTIF('365RE'!$V$6:$V$201,'Tasks 6,7'!C13) -> 2 | E13: =D13/$D$18 -> 0.01025641 | F13: =F12+E13 -> 0.97435897
C14: UK | D14: =COUNTIF('365RE'!$V$6:$V$201,'Tasks 6,7'!C14) -> 2 | E14: =D14/$D$18 -> 0.01025641 | F14: =F13+E14 -> 0.98461538
C15: Denmark | D15: =COUNTIF('365RE'!$V$6:$V$201,'Tasks 6,7'!C15) -> 1 | E15: =D15/$D$18 -> 0.0051282051 | F15: =F14+E15 -> 0.98974359
C16: Germany | D16: =COUNTIF('365RE'!$V$6:$V$201,'Tasks 6,7'!C16) -> 1 | E16: =D16/$D$18 -> 0.0051282051 | F16: =F15+E16 -> 0.99487179
C17: Mexico | D17: =COUNTIF('365RE'!$V$6:$V$201,'Tasks 6,7'!C17) -> 1 | E17: =D17/$D$18 -> 0.0051282051 | F17: =F16+E17 -> 1
C18: Sum | D18: =SUM(D10:D17) -> 195 | E18: =SUM(E10:E17) -> 1

Sheet Tasks 8,9
B1: 365 DataScience RE California Database
B2: Measures of central tendency, asymmetry and variability
B4: Task 8: Calculate the mean, median, mode, skewness, variance and standard deviation of Price for all properties, no matter if sold or not.
B5: Task 9: Interpret the measures.
C7: Mean | D7: =AVERAGE('365RE'!I6:I272) -> 281171.9 | F7: The mean and the median are very cose together indicating that the dispersion of house prices are very close together
C8: Median | D8: =MEDIAN('365RE'!I6:I272) -> 249075.66 | F8: However, this is slighly skewed by the most frequently occuring value of $460K as demonstrated by the skewness factor
C9: Mode | D9: =_xlfn.MODE.SNGL('365RE'!I6:I272) -> 460001.26
C10: Skewness | D10: =SKEW('365RE'!I6:I272) -> 1.0960149 | F10: The variance shows a wide dispersion about the mean possibly by one outlier (expensive property) or the frequently occuring price
C11: Variance | D11: =_xlfn.VAR.P('365RE'!I6:I272) -> 7.9124716e+09
C12: Standard deviation | D12: =_xlfn.STDEV.P('365RE'!I6:I272) -> 88952.075

Sheet Task 10
B1: 365 DataScience RE California Database
B2: Measures of relationship between variables
B4: Task 10: Calculate the covariance and correlation coefficient between Price and Area, no matter if the property is sold or not. Is the result in line with the scatter plot?
B6: Covariance | C6: =_xlfn.COVARIANCE.P('365RE'!I6:I272,'365RE'!H6:H272) -> 24057281
B7: Corrolation | C7: =CORREL('365RE'!I6:I272,'365RE'!H6:H272) -> 0.95108738
B9: Corrolation aligns with the scatter plot
